Workbook

Sheet Sheet1
A1: NTC | B1: 77 | C1: =IFERROR(IF(B8=0, 0,B8+ 1),0) -> 85 | D1: =IFERROR(IF(C8=0, 0,C8+ 1),0) -> 93 | E1: =IFERROR(IF(D8=0, 0,D8+ 1),0) -> 101 | F1: =IFERROR(IF(E8=0, 0,E8+ 1),0) -> 109 | G1: =IFERROR(IF(F8=0, 0,F8+ 1),0) -> 117 | H1: =IFERROR(IF(G8=0, 0,G8+ 1),0) -> 125 | I1: =IFERROR(IF(H8=0, 0,H8+ 1),0) -> 0 | J1: =IFERROR(IF(I8=0, 0,I8+ 1),0) -> 0 | K1: =IFERROR(IF(J8=0, 0,J8+ 1),0) -> 0 | L1: WNV 1:1000
A2: Neg Mosq RNA | B2: =IFERROR(IF(B1=0, 0, B1+1), 0) -> 78 | C2: =IFERROR(IF(C1=0, 0, C1+1), 0) -> 86 | D2: =IFERROR(IF(D1=0, 0, D1+1), 0) -> 94 | E2: =IFERROR(IF(E1=0, 0, E1+1), 0) -> 102 | F2: =IFERROR(IF(F1=0, 0, F1+1), 0) -> 110 | G2: =IFERROR(IF(G1=0, 0, G1+1), 0) -> 118 | H2: =IFERROR(IF(H1=0, 0, H1+1), 0) -> 126 | I2: =IFERROR(IF(I1=0, 0, I1+1), 0) -> 0 | ... K2: =IFERROR(IF(K1=0, 0, K1+1), 0) -> 0 | L2: WNV RNA
B3: =IFERROR(IF(B2=0, 0, B2+1), 0) -> 79 | C3: =IFERROR(IF(C2=0, 0, C2+1), 0) -> 87 | D3: =IFERROR(IF(D2=0, 0, D2+1), 0) -> 95 | E3: =IFERROR(IF(E2=0, 0, E2+1), 0) -> 103 | F3: =IFERROR(IF(F2=0, 0, F2+1), 0) -> 111 | G3: =IFERROR(IF(G2=0, 0, G2+1), 0) -> 119 | H3: =IFERROR(IF(H2=0, 0, H2+1), 0) -> 127 | I3: =IFERROR(IF(I2=0, 0, I2+1), 0) -> 0 | ... K3: =IFERROR(IF(K2=0, 0, K2+1), 0) -> 0
B4: =IFERROR(IF(B3=0, 0, B3+1), 0) -> 80 | C4: =IFERROR(IF(C3=0, 0, C3+1), 0) -> 88 | D4: =IFERROR(IF(D3=0, 0, D3+1), 0) -> 96 | E4: =IFERROR(IF(E3=0, 0, E3+1), 0) -> 104 | F4: =IFERROR(IF(F3=0, 0, F3+1), 0) -> 112 | G4: =IFERROR(IF(G3=0, 0, G3+1), 0) -> 120 | H4: =IFERROR(IF(H3=0, 0, H3+1), 0) -> 128 | I4: =IFERROR(IF(I3=0, 0, I3+1), 0) -> 0 | ... K4: =IFERROR(IF(K3=0, 0, K3+1), 0) -> 0
B5: =IFERROR(IF(B4=0, 0, B4+1), 0) -> 81 | C5: =IFERROR(IF(C4=0, 0, C4+1), 0) -> 89 | D5: =IFERROR(IF(D4=0, 0, D4+1), 0) -> 97 | E5: =IFERROR(IF(E4=0, 0, E4+1), 0) -> 105 | F5: =IFERROR(IF(F4=0, 0, F4+1), 0) -> 113 | G5: =IFERROR(IF(G4=0, 0, G4+1), 0) -> 121 | H5: 0 | I5: =IFERROR(IF(I4=0, 0, I4+1), 0) -> 0 | J5: =IFERROR(IF(J4=0, 0, J4+1), 0) -> 0 | K5: =IFERROR(IF(K4=0, 0, K4+1), 0) -> 0 | L5: SLE RNA
B6: =IFERROR(IF(B5=0, 0,B5+ 1),0) -> 82 | C6: =IFERROR(IF(C5=0, 0,C5+ 1),0) -> 90 | D6: =IFERROR(IF(D5=0, 0,D5+ 1),0) -> 98 | E6: =IFERROR(IF(E5=0, 0,E5+ 1),0) -> 106 | F6: =IFERROR(IF(F5=0, 0,F5+ 1),0) -> 114 | G6: =IFERROR(IF(G5=0, 0,G5+ 1),0) -> 122 | H6: =IFERROR(IF(H5=0, 0,H5+ 1),0) -> 0 | I6: =IFERROR(IF(I5=0, 0,I5+ 1),0) -> 0 | ... K6: =IFERROR(IF(K5=0, 0,K5+ 1),0) -> 0
B7: =IFERROR(IF(B6=0, 0,B6+ 1),0) -> 83 | C7: =IFERROR(IF(C6=0, 0,C6+ 1),0) -> 91 | D7: =IFERROR(IF(D6=0, 0,D6+ 1),0) -> 99 | E7: =IFERROR(IF(E6=0, 0,E6+ 1),0) -> 107 | F7: =IFERROR(IF(F6=0, 0,F6+ 1),0) -> 115 | G7: =IFERROR(IF(G6=0, 0,G6+ 1),0) -> 123 | H7: =IFERROR(IF(H6=0, 0,H6+ 1),0) -> 0 | I7: =IFERROR(IF(I6=0, 0,I6+ 1),0) -> 0 | ... K7: =IFERROR(IF(K6=0, 0,K6+ 1),0) -> 0
B8: =IFERROR(IF(B7=0, 0,B7+ 1),0) -> 84 | C8: =IFERROR(IF(C7=0, 0,C7+ 1),0) -> 92 | D8: =IFERROR(IF(D7=0, 0,D7+ 1),0) -> 100 | E8: =IFERROR(IF(E7=0, 0,E7+ 1),0) -> 108 | F8: =IFERROR(IF(F7=0, 0,F7+ 1),0) -> 116 | G8: =IFERROR(IF(G7=0, 0,G7+ 1),0) -> 124 | H8: =IFERROR(IF(H7=0, 0,H7+ 1),0) -> 0 | I8: =IFERROR(IF(I7=0, 0,I7+ 1),0) -> 0 | ... K8: =IFERROR(IF(K7=0, 0,K7+ 1),0) -> 0 | L8: EEE RNA
A11: Well | B11: Sample Name | C11: Detector
A12: 1 | B12: =A1 -> NTC | C12: SLE 1
A13: 1 | B13: =A1 -> NTC | C13: EEE
A14: 1 | B14: =A1 -> NTC | C14: WNV 1
A15: 2 | B15: =B1 -> 77 | C15: SLE 1
A16: 2 | B16: =B1 -> 77 | C16: EEE
A17: 2 | B17: =B1 -> 77 | C17: WNV 1
A18: 3 | B18: =C1 -> 85 | C18: SLE 1
A19: 3 | B19: =C1 -> 85 | C19: EEE
A20: 3 | B20: =C1 -> 85 | C20: WNV 1
A21: 4 | B21: =D1 -> 93 | C21: SLE 1
A22: 4 | B22: =D1 -> 93 | C22: EEE
A23: 4 | B23: =D1 -> 93 | C23: WNV 1
A24: 5 | B24: =E1 -> 101 | C24: SLE 1
A25: 5 | B25: =E1 -> 101 | C25: EEE
A26: 5 | B26: =E1 -> 101 | C26: WNV 1
A27: 6 | B27: =F1 -> 109 | C27: SLE 1
A28: 6 | B28: =F1 -> 109 | C28: EEE
A29: 6 | B29: =F1 -> 109 | C29: WNV 1
A30: 7 | B30: =G1 -> 117 | C30: SLE 1
A31: 7 | B31: =G1 -> 117 | C31: EEE
A32: 7 | B32: =G1 -> 117 | C32: WNV 1
A33: 8 | B33: =H1 -> 125 | C33: SLE 1
A34: 8 | B34: =H1 -> 125 | C34: EEE
A35: 8 | B35: =H1 -> 125 | C35: WNV 1
A36: 9 | B36: =I1 -> 0 | C36: SLE 1
A37: 9 | B37: =I1 -> 0 | C37: EEE
A38: 9 | B38: =I1 -> 0 | C38: WNV 1
A39: 10 | B39: =J1 -> 0 | C39: SLE 1
A40: 10 | B40: =J1 -> 0 | C40: EEE
A41: 10 | B41: =J1 -> 0 | C41: WNV 1
A42: 11 | B42: =K1 -> 0 | C42: SLE 1
...

Sheet Sheet2
A1: *** SDS Setup File Version | B1: 3
A2: *** Output Plate Size | B2: 96
A3: *** Output Plate ID | B3: Culex.sds
A4: *** Number of Detectors | B4: 3
A5: Detector | B5: Reporter | C5: Quencher | D5: Description | E5: Comments
A6: SLE 1 | B6: CY5
A7: EEE | B7: VIC
A8: WNV 1 | B8: FAM
A9: Well | B9: Sample Name | C9: Detector | D9: Task | E9: Quantity
A10: 1 | B10: =[1]Sheet1!$B12 -> NTC | C10: =[1]Sheet1!$C12 -> SLE 1 | D10: UNKN
A11: 1 | B11: =[1]Sheet1!$B13 -> NTC | C11: =[1]Sheet1!$C13 -> EEE | D11: UNKN
A12: 1 | B12: =[1]Sheet1!$B14 -> NTC | C12: =[1]Sheet1!$C14 -> WNV 1 | D12: UNKN
A13: 2 | B13: =IFERROR(IF(AND(ISNUMBER(Sheet1!B15), Sheet1!B15=INT(Sheet1!B15), Sheet1!B15<>0), "C"&Sheet1!B15, Sheet1!B15), Sheet1!B15) -> C77 | C13: =[1]Sheet1!$C15 -> SLE 1 | D13: UNKN
A14: 2 | B14: =IFERROR(IF(AND(ISNUMBER(Sheet1!B16), Sheet1!B16=INT(Sheet1!B16), Sheet1!B16<>0), "C"&Sheet1!B16, Sheet1!B16), Sheet1!B16) -> C77 | C14: =[1]Sheet1!$C16 -> EEE | D14: UNKN
A15: 2 | B15: =IFERROR(IF(AND(ISNUMBER(Sheet1!B17), Sheet1!B17=INT(Sheet1!B17), Sheet1!B17<>0), "C"&Sheet1!B17, Sheet1!B17), Sheet1!B17) -> C77 | C15: =[1]Sheet1!$C17 -> WNV 1 | D15: UNKN
A16: 3 | B16: =IFERROR(IF(AND(ISNUMBER(Sheet1!B18), Sheet1!B18=INT(Sheet1!B18), Sheet1!B18<>0), "C"&Sheet1!B18, Sheet1!B18), Sheet1!B18) -> C85 | C16: =[1]Sheet1!$C18 -> SLE 1 | D16: UNKN
A17: 3 | B17: =IFERROR(IF(AND(ISNUMBER(Sheet1!B19), Sheet1!B19=INT(Sheet1!B19), Sheet1!B19<>0), "C"&Sheet1!B19, Sheet1!B19), Sheet1!B19) -> C85 | C17: =[1]Sheet1!$C19 -> EEE | D17: UNKN
A18: 3 | B18: =IFERROR(IF(AND(ISNUMBER(Sheet1!B20), Sheet1!B20=INT(Sheet1!B20), Sheet1!B20<>0), "C"&Sheet1!B20, Sheet1!B20), Sheet1!B20) -> C85 | C18: =[1]Sheet1!$C20 -> WNV 1 | D18: UNKN
A19: 4 | B19: =IFERROR(IF(AND(ISNUMBER(Sheet1!B21), Sheet1!B21=INT(Sheet1!B21), Sheet1!B21<>0), "C"&Sheet1!B21, Sheet1!B21), Sheet1!B21) -> C93 | C19: =[1]Sheet1!$C21 -> SLE 1 | D19: UNKN
A20: 4 | B20: =IFERROR(IF(AND(ISNUMBER(Sheet1!B22), Sheet1!B22=INT(Sheet1!B22), Sheet1!B22<>0), "C"&Sheet1!B22, Sheet1!B22), Sheet1!B22) -> C93 | C20: =[1]Sheet1!$C22 -> EEE | D20: UNKN
A21: 4 | B21: =IFERROR(IF(AND(ISNUMBER(Sheet1!B23), Sheet1!B23=INT(Sheet1!B23), Sheet1!B23<>0), "C"&Sheet1!B23, Sheet1!B23), Sheet1!B23) -> C93 | C21: =[1]Sheet1!$C23 -> WNV 1 | D21: UNKN
A22: 5 | B22: =IFERROR(IF(AND(ISNUMBER(Sheet1!B24), Sheet1!B24=INT(Sheet1!B24), Sheet1!B24<>0), "C"&Sheet1!B24, Sheet1!B24), Sheet1!B24) -> C101 | C22: =[1]Sheet1!$C24 -> SLE 1 | D22: UNKN
A23: 5 | B23: =IFERROR(IF(AND(ISNUMBER(Sheet1!B25), Sheet1!B25=INT(Sheet1!B25), Sheet1!B25<>0), "C"&Sheet1!B25, Sheet1!B25), Sheet1!B25) -> C101 | C23: =[1]Sheet1!$C25 -> EEE | D23: UNKN
A24: 5 | B24: =IFERROR(IF(AND(ISNUMBER(Sheet1!B26), Sheet1!B26=INT(Sheet1!B26), Sheet1!B26<>0), "C"&Sheet1!B26, Sheet1!B26), Sheet1!B26) -> C101 | C24: =[1]Sheet1!$C26 -> WNV 1 | D24: UNKN
... A42: 11 | B42: =IFERROR(IF(AND(ISNUMBER(Sheet1!B44), Sheet1!B44=INT(Sheet1!B44), Sheet1!B44<>0), "C"&Sheet1!B44, Sheet1!B44), Sheet1!B44) -> 0 | C42: =[1]Sheet1!$C44 -> WNV 1 | D42: UNKN
A43: 12 | B43: =[1]Sheet1!$B45 -> WNV 1:1000 | C43: =[1]Sheet1!$C45 -> SLE 1 | D43: UNKN
A44: 12 | B44: =[1]Sheet1!$B46 -> WNV 1:1000 | C44: =[1]Sheet1!$C46 -> EEE | D44: UNKN
A45: 12 | B45: =[1]Sheet1!$B47 -> WNV 1:1000 | C45: =[1]Sheet1!$C47 -> WNV 1 | D45: UNKN
A46: 13 | B46: =[1]Sheet1!$B48 -> Neg Mosq RNA | C46: =[1]Sheet1!$C48 -> SLE 1 | D46: UNKN
A47: 13 | B47: =[1]Sheet1!$B49 -> Neg Mosq RNA | C47: =[1]Sheet1!$C49 -> EEE | D47: UNKN
A48: 13 | B48: =[1]Sheet1!$B50 -> Neg Mosq RNA | C48: =[1]Sheet1!$C50 -> WNV 1 | D48: UNKN
A49: 14 | B49: =IFERROR(IF(AND(ISNUMBER(Sheet1!B51), Sheet1!B51=INT(Sheet1!B51), Sheet1!B51<>0), "C"&Sheet1!B51, Sheet1!B51), Sheet1!B51) -> C78 | C49: =[1]Sheet1!$C51 -> SLE 1 | D49: UNKN
A50: 14 | B50: =IFERROR(IF(AND(ISNUMBER(Sheet1!B52), Sheet1!B52=INT(Sheet1!B52), Sheet1!B52<>0), "C"&Sheet1!B52, Sheet1!B52), Sheet1!B52) -> C78 | C50: =[1]Sheet1!$C52 -> EEE | D50: UNKN
A51: 14 | B51: =IFERROR(IF(AND(ISNUMBER(Sheet1!B53), Sheet1!B53=INT(Sheet1!B53), Sheet1!B53<>0), "C"&Sheet1!B53, Sheet1!B53), Sheet1!B53) -> C78 | C51: =[1]Sheet1!$C53 -> WNV 1 | D51: UNKN
A52: 15 | B52: =IFERROR(IF(AND(ISNUMBER(Sheet1!B54), Sheet1!B54=INT(Sheet1!B54), Sheet1!B54<>0), "C"&Sheet1!B54, Sheet1!B54), Sheet1!B54) -> C86 | C52: =[1]Sheet1!$C54 -> SLE 1 | D52: UNKN
A53: 15 | B53: =IFERROR(IF(AND(ISNUMBER(Sheet1!B55), Sheet1!B55=INT(Sheet1!B55), Sheet1!B55<>0), "C"&Sheet1!B55, Sheet1!B55), Sheet1!B55) -> C86 | C53: =[1]Sheet1!$C55 -> EEE | D53: UNKN
A54: 15 | B54: =IFERROR(IF(AND(ISNUMBER(Sheet1!B56), Sheet1!B56=INT(Sheet1!B56), Sheet1!B56<>0), "C"&Sheet1!B56, Sheet1!B56), Sheet1!B56) -> C86 | C54: =[1]Sheet1!$C56 -> WNV 1 | D54: UNKN
A55: 16 | B55: =IFERROR(IF(AND(ISNUMBER(Sheet1!B57), Sheet1!B57=INT(Sheet1!B57), Sheet1!B57<>0), "C"&Sheet1!B57, Sheet1!B57), Sheet1!B57) -> C94 | C55: =[1]Sheet1!$C57 -> SLE 1 | D55: UNKN
A56: 16 | B56: =IFERROR(IF(AND(ISNUMBER(Sheet1!B58), Sheet1!B58=INT(Sheet1!B58), Sheet1!B58<>0), "C"&Sheet1!B58, Sheet1!B58), Sheet1!B58) -> C94 | C56: =[1]Sheet1!$C58 -> EEE | D56: UNKN
A57: 16 | B57: =IFERROR(IF(AND(ISNUMBER(Sheet1!B59), Sheet1!B59=INT(Sheet1!B59), Sheet1!B59<>0), "C"&Sheet1!B59, Sheet1!B59), Sheet1!B59) -> C94 | C57: =[1]Sheet1!$C59 -> WNV 1 | D57: UNKN
...
